{"nbformat":4,"nbformat_minor":0,"metadata":{"colab":{"provenance":[],"authorship_tag":"ABX9TyOiZLf1Db3mjZQw63cX6Vmn"},"kernelspec":{"name":"python3","display_name":"Python 3"},"language_info":{"name":"python"}},"cells":[{"cell_type":"markdown","source":["#Errors in python\n","  In general we can classify errors in a program in three types:\n","1.   Compile-time\n","2.   Run-time\n","2.   logical errors\n","\n","\n","\n","\n"],"metadata":{"id":"HjO--kSZ_ITT"}},{"cell_type":"markdown","source":["##Compile time error\n","these are the syntactical errors found in the code due to which a program fails to compile."],"metadata":{"id":"PIFVwCWZ_wQR"}},{"cell_type":"code","source":["x=1\n","if x==1\n","  print(\"where is the collon?\")"],"metadata":{"id":"0m0kbq8zADpB"},"execution_count":null,"outputs":[]},{"cell_type":"markdown","source":["##Runtime Error\n","When PVM (python virtual machine) cannot execute the Byte code it flage runtime error"],"metadata":{"id":"o1BVbEKlAkHe"}},{"cell_type":"code","source":["def concat(a,b):\n","  print(a,b)\n","concat(\"hello\", 34)"],"metadata":{"id":"g7RxJLQ7BDKK"},"execution_count":null,"outputs":[]},{"cell_type":"markdown","source":["##Logical Error\n","This error occurs when an programmer makes a logical error\n"],"metadata":{"id":"5L2RcneMBRIk"}},{"cell_type":"code","source":["def calculate_average(numbers):\n","    total = 0\n","    count = 0\n","\n","    for num in numbers:\n","        total += num\n","        count += 0      # This line contains the logical error\n","\n","    average = total / count\n","\n","    return average\n","\n","# Example usage:\n","numbers = [10, 20, 30, 40, 50]\n","average = calculate_average(numbers)\n","print(\"Average:\", average)\n"],"metadata":{"id":"GvP9JcARGEak"},"execution_count":null,"outputs":[]},{"cell_type":"markdown","source":["## **Explain Python Built-in-Exceptions.**"],"metadata":{"id":"UP0YwsbBHwLO"}},{"cell_type":"markdown","source":["### In Python, built-in exceptions are predefined classes that represent various types of errors or exceptional conditions that can occur during program execution. These exceptions are raised (or thrown) when an error occurs in Python code, and they can be caught (or handled) by using exception handling mechanisms like try and except blocks.\n","\n","**SyntaxError:** Raised when the Python parser encounters a syntax error in the code. It indicates that the code is not syntactically valid Python.\n","\n","**IndentationError:** Raised when there's an improper indentation in the code, typically due to inconsistent use of spaces or tabs.\n","\n","NameError: Raised when an identifier (variable name, function name, etc.) is not found in the local or global scope.\n","\n","TypeError: Raised when an operation or function is applied to an object of an inappropriate type.\n","\n","ValueError: Raised when a built-in operation or function receives an argument with the correct type but an inappropriate value.\n","\n","KeyError: Raised when a dictionary key is not found in the set of existing keys.\n","\n","IndexError: Raised when a sequence subscript (index) is out of range.\n","\n","FileNotFoundError: Raised when a file or directory is requested but cannot be found.\n","\n","ZeroDivisionError: Raised when division or modulo operation is performed with zero as the divisor.\n","\n","AttributeError: Raised when an attribute reference or assignment fails because the specified attribute doesn't exist.\n","\n","ImportError: Raised when an import statement fails to find the module, or when a from ... import ... statement cannot find the specified name in the module.\n","\n","KeyboardInterrupt: Raised when the user interrupts the execution of the program (e.g., by pressing Ctrl+C)."],"metadata":{"id":"Eoqw5ZofH1ZY"}},{"cell_type":"markdown","source":["## **When the value error occurs in Python?**"],"metadata":{"id":"rlsYiDKgIl0E"}},{"cell_type":"markdown","source":["ValueError: Raised when a built-in operation or function receives an argument with the correct type but an inappropriate value."],"metadata":{"id":"-ViZlM6zJMuO"}},{"cell_type":"code","source":["my_list = [1, 2, 3]\n","print(my_list[5])  # ValueError: list index out of range\n"],"metadata":{"id":"kX-Stnh0Jfjk"},"execution_count":null,"outputs":[]},{"cell_type":"code","source":["num=int(\"abc\")"],"metadata":{"id":"n_4zrfBEHg1o"},"execution_count":null,"outputs":[]},{"cell_type":"markdown","source":["## Differentiate between Syntax error and exception"],"metadata":{"id":"DO4lC6eyJp8t"}},{"cell_type":"markdown","source":["Syntax errors occur during the parsing (or compilation) phase of Python code, before the code is executed.\n","They are caused by violations of the Python syntax rules, such as incorrect indentation, missing or misplaced punctuation, or incorrect keyword usage\n","\n","Exceptions, on the other hand, occur during the execution phase of Python code, after the code has been successfully parsed and is being executed.\n","Exceptions represent runtime errors or exceptional conditions that occur while the program is running, such as division by zero, attempting to access an index that is out of range, or trying to open a file that does not exist.\n","Exceptions can be caused by a variety of factors, including user input, external resources (e.g., files, network connections), and program logic."],"metadata":{"id":"GX47DqrUJsT7"}},{"cell_type":"code","source":["#Syntax error\n","num = int(input(\"Enter a number\"))\n","i(num<10):\n","  print(\"less than 10\")\n","#exception\n","a=10\n","b=0\n","c=a/b\n","print(c)\n"],"metadata":{"id":"rtA8mhRqHzRx"},"execution_count":null,"outputs":[]},{"cell_type":"markdown","source":["## Give an example of  value error and key error\n","\n"],"metadata":{"id":"Z8imI8hKKTBy"}},{"cell_type":"markdown","source":["ValueError occurs when a built-in operation or function receives an argument with the correct type but an inappropriate value.\n"],"metadata":{"id":"MHK1Kpd3KXGt"}},{"cell_type":"code","source":["my_list = [1, 2, 3]\n","print(my_list[5])  # ValueError: list index out of range"],"metadata":{"id":"EwKnP47DKdK_"},"execution_count":null,"outputs":[]},{"cell_type":"markdown","source":["KeyError occurs when a dictionary key is not found in the set of existing keys."],"metadata":{"id":"DYWXHJoHKhNz"}},{"cell_type":"code","source":["# Accessing a non-existent key in a dictionary\n","my_dict = {'a': 1, 'b': 2}\n","print(my_dict['c'])  # Raises KeyError: 'c'\n"],"metadata":{"id":"UraeHvRuKjsp"},"execution_count":null,"outputs":[]},{"cell_type":"markdown","source":["## How exception handling works in Python?"],"metadata":{"id":"Z_K_q8KXKeDI"}},{"cell_type":"markdown","source":["\n","Exception handling in Python allows you to handle errors that occur during the execution of a program gracefully, preventing the program from crashing abruptly. Here's how it works:\n","\n","**Try block: **You place the code that might raise an exception inside a try block. If an exception occurs within this block, Python searches for an appropriate except block to handle it.\n","\n","**Except block:** If an exception occurs within the try block, Python looks for an except block that matches the type of exception raised. If a matching except block is found, its code is executed.\n","**Finally block (optional):** The finally block is always executed, regardless of whether an exception occurred in the try block. This block is useful for cleaning up resources, such as closing files or database connections."],"metadata":{"id":"g5qf8uxtKf0D"}},{"cell_type":"code","source":["try:\n","    # code that might raise an exception\n","    # e.g., division by zero or accessing a non-existent index\n","except SomeException:\n","    # handle SomeException\n","except AnotherException:\n","    # handle AnotherException\n","else:\n","    # optional block that executes if no exception occurs\n","finally:\n","    # optional block that always executes, whether an exception occurred or not\n"],"metadata":{"id":"u3YyFE8tK9NM"},"execution_count":null,"outputs":[]}]}